Workbook

Sheet ProcessedResults
A1: ID | B1: Date | C1: AccuracyLaser | D1: AccuracyNonLaser | E1: OmissionsLaser | F1: OmissionsNonLaser | G1: LaserReward | H1: NonLaserReward | I1: LaserTrials | J1: NonLaserTrials | K1: oLaserPercent | L1: oNonLaserPercent | M1: LatencyLaser | N1: LatencyNonLaser | O1: Angle | P1: Power | Q1: Visualize | R1: CleanID | S1: SEARCH
A2: 1029 | B2: 2025-11-22 | C2: 54.166667 | D2: 55 | E2: 0 | F2: 0 | G2: 65 | H2: 66 | I2: 120 | J2: 120 | K2: 0 | L2: 0 | M2: 0.18281538 | N2: 0.19430303 | O2: =_xlfn.XLOOKUP(S2, AnglePowerMatching!$H:$H, AnglePowerMatching!$C:$C, "NaN") -> 66 | P2: =_xlfn.XLOOKUP(S2, AnglePowerMatching!$H:$H, AnglePowerMatching!$D:$D, "NaN") -> 3 | Q2: =NOT(OR(C2=0,D2=0)) -> TRUE | R2: =VALUE(_xlfn.TEXTBEFORE(A2, {"L","R"}, , , , A2)) -> 1029 | S2: =R2 & TEXT(B2, "yyyymmdd") -> 102920251122
A3: 1029 | B3: 2025-11-23 | C3: 53.333333 | D3: 51.666667 | E3: 0 | F3: 0 | G3: 64 | H3: 62 | I3: 120 | J3: 120 | K3: 0 | L3: 0 | M3: 0.27225 | N3: 0.28053226 | O3: =_xlfn.XLOOKUP(S3, AnglePowerMatching!$H:$H, AnglePowerMatching!$C:$C, "NaN") -> 66 | P3: =_xlfn.XLOOKUP(S3, AnglePowerMatching!$H:$H, AnglePowerMatching!$D:$D, "NaN") -> 5 | Q3: =NOT(OR(C3=0,D3=0)) -> TRUE | R3: =VALUE(_xlfn.TEXTBEFORE(A3, {"L","R"}, , , , A3)) -> 1029 | S3: =R3 & TEXT(B3, "yyyymmdd") -> 102920251123
A4: 1029 | B4: 2025-11-24 | C4: 51.666667 | D4: 46.666667 | E4: 0 | F4: 0 | G4: 62 | H4: 56 | I4: 120 | J4: 120 | K4: 0 | L4: 0 | M4: 0.29008065 | N4: 0.20426786 | O4: =_xlfn.XLOOKUP(S4, AnglePowerMatching!$H:$H, AnglePowerMatching!$C:$C, "NaN") -> 66 | P4: =_xlfn.XLOOKUP(S4, AnglePowerMatching!$H:$H, AnglePowerMatching!$D:$D, "NaN") -> 10 | Q4: =NOT(OR(C4=0,D4=0)) -> TRUE | R4: =VALUE(_xlfn.TEXTBEFORE(A4, {"L","R"}, , , , A4)) -> 1029 | S4: =R4 & TEXT(B4, "yyyymmdd") -> 102920251124
A5: 1029 | B5: 2025-12-12 | C5: 65.833333 | D5: 65.833333 | E5: 0 | F5: 0 | G5: 79 | H5: 79 | I5: 120 | J5: 120 | K5: 0 | L5: 0 | M5: 0.26475949 | N5: 0.24287342 | O5: =_xlfn.XLOOKUP(S5, AnglePowerMatching!$H:$H, AnglePowerMatching!$C:$C, "NaN") -> 90 | P5: =_xlfn.XLOOKUP(S5, AnglePowerMatching!$H:$H, AnglePowerMatching!$D:$D, "NaN") -> 3 | Q5: =NOT(OR(C5=0,D5=0)) -> TRUE | R5: =VALUE(_xlfn.TEXTBEFORE(A5, {"L","R"}, , , , A5)) -> 1029 | S5: =R5 & TEXT(B5, "yyyymmdd") -> 102920251212
A6: 1029 | B6: 2025-12-13 | C6: 82.5 | D6: 86.419753 | E6: 40 | F6: 39 | G6: 66 | H6: 70 | I6: 120 | J6: 120 | K6: 33.333333 | L6: 32.5 | M6: 0.42874242 | N6: 0.34355714 | O6: =_xlfn.XLOOKUP(S6, AnglePowerMatching!$H:$H, AnglePowerMatching!$C:$C, "NaN") -> 90 | P6: =_xlfn.XLOOKUP(S6, AnglePowerMatching!$H:$H, AnglePowerMatching!$D:$D, "NaN") -> 5 | Q6: =NOT(OR(C6=0,D6=0)) -> TRUE | R6: =VALUE(_xlfn.TEXTBEFORE(A6, {"L","R"}, , , , A6)) -> 1029 | S6: =R6 & TEXT(B6, "yyyymmdd") -> 102920251213
A7: 1029 | B7: 2025-12-15 | C7: 81.034483 | D7: 70.175439 | E7: 62 | F7: 63 | G7: 47 | H7: 40 | I7: 120 | J7: 120 | K7: 51.666667 | L7: 52.5 | M7: 0.96259574 | N7: 0.9585 | O7: =_xlfn.XLOOKUP(S7, AnglePowerMatching!$H:$H, AnglePowerMatching!$C:$C, "NaN") -> 90 | P7: =_xlfn.XLOOKUP(S7, AnglePowerMatching!$H:$H, AnglePowerMatching!$D:$D, "NaN") -> 10 | Q7: =NOT(OR(C7=0,D7=0)) -> TRUE | R7: =VALUE(_xlfn.TEXTBEFORE(A7, {"L","R"}, , , , A7)) -> 1029 | S7: =R7 & TEXT(B7, "yyyymmdd") -> 102920251215
A8: 1029 | B8: 2025-12-16 | C8: 36.595745 | D8: 36.820084 | E8: 5 | F8: 1 | G8: 86 | H8: 88 | I8: 240 | J8: 240 | K8: 2.0833333 | L8: 0.41666667 | M8: 0.30010465 | N8: 0.28431818 | O8: =_xlfn.XLOOKUP(S8, AnglePowerMatching!$H:$H, AnglePowerMatching!$C:$C, "NaN") -> 90 | P8: =_xlfn.XLOOKUP(S8, AnglePowerMatching!$H:$H, AnglePowerMatching!$D:$D, "NaN") -> 10 | Q8: =NOT(OR(C8=0,D8=0)) -> TRUE | R8: =VALUE(_xlfn.TEXTBEFORE(A8, {"L","R"}, , , , A8)) -> 1029 | S8: =R8 & TEXT(B8, "yyyymmdd") -> 102920251216
A9: 1029 | B9: 2025-12-17 | C9: 64.285714 | D9: 65.789474 | E9: 12 | F9: 11 | G9: 72 | H9: 75 | I9: 124 | J9: 125 | K9: 9.6774194 | L9: 8.8 | M9: 0.29847222 | N9: 0.25242667 | O9: =_xlfn.XLOOKUP(S9, AnglePowerMatching!$H:$H, AnglePowerMatching!$C:$C, "NaN") -> 90 | P9: =_xlfn.XLOOKUP(S9, AnglePowerMatching!$H:$H, AnglePowerMatching!$D:$D, "NaN") -> 10 | Q9: =NOT(OR(C9=0,D9=0)) -> TRUE | R9: =VALUE(_xlfn.TEXTBEFORE(A9, {"L","R"}, , , , A9)) -> 1029 | S9: =R9 & TEXT(B9, "yyyymmdd") -> 102920251217
A10: 1029 | B10: 2025-12-18 | C10: 62.608696 | D10: 55.555556 | E10: 5 | F10: 3 | G10: 72 | H10: 65 | I10: 120 | J10: 120 | K10: 4.1666667 | L10: 2.5 | M10: 0.26394444 | N10: 0.23587692 | O10: =_xlfn.XLOOKUP(S10, AnglePowerMatching!$H:$H, AnglePowerMatching!$C:$C, "NaN") -> 90 | P10: =_xlfn.XLOOKUP(S10, AnglePowerMatching!$H:$H, AnglePowerMatching!$D:$D, "NaN") -> 5 | Q10: =NOT(OR(C10=0,D10=0)) -> TRUE | R10: =VALUE(_xlfn.TEXTBEFORE(A10, {"L","R"}, , , , A10)) -> 1029 | S10: =R10 & TEXT(B10, "yyyymmdd") -> 102920251218
A11: 1029 | B11: 2025-12-30 | C11: 60.504202 | D11: 62.280702 | E11: 1 | F11: 6 | G11: 72 | H11: 71 | I11: 120 | J11: 120 | K11: 0.83333333 | L11: 5 | M11: 0.28647222 | N11: 0.2645493 | O11: =_xlfn.XLOOKUP(S11, AnglePowerMatching!$H:$H, AnglePowerMatching!$C:$C, "NaN") -> 90 | P11: =_xlfn.XLOOKUP(S11, AnglePowerMatching!$H:$H, AnglePowerMatching!$D:$D, "NaN") -> 10 | Q11: =NOT(OR(C11=0,D11=0)) -> TRUE | R11: =VALUE(_xlfn.TEXTBEFORE(A11, {"L","R"}, , , , A11)) -> 1029 | S11: =R11 & TEXT(B11, "yyyymmdd") -> 102920251230
A12: 1029 | B12: 2025-12-31 | C12: 73.684211 | D12: 76.229508 | E12: 22 | F12: 14 | G12: 84 | H12: 93 | I12: 136 | J12: 136 | K12: 16.176471 | L12: 10.294118 | M12: 0.28832143 | N12: 0.27991398 | O12: =_xlfn.XLOOKUP(S12, AnglePowerMatching!$H:$H, AnglePowerMatching!$C:$C, "NaN") -> 90 | P12: =_xlfn.XLOOKUP(S12, AnglePowerMatching!$H:$H, AnglePowerMatching!$D:$D, "NaN") -> 5 | Q12: =NOT(OR(C12=0,D12=0)) -> TRUE | R12: =VALUE(_xlfn.TEXTBEFORE(A12, {"L","R"}, , , , A12)) -> 1029 | S12: =R12 & TEXT(B12, "yyyymmdd") -> 102920251231
A13: 1029 | B13: 2026-01-07 | C13: 55.833333 | D13: 51.260504 | E13: 0 | F13: 1 | G13: 67 | H13: 61 | I13: 120 | J13: 120 | K13: 0 | L13: 0.83333333 | M13: 0.31301493 | N13: 0.26309836 | O13: =_xlfn.XLOOKUP(S13, AnglePowerMatching!$H:$H, AnglePowerMatching!$C:$C, "NaN") -> 35 | P13: =_xlfn.XLOOKUP(S13, AnglePowerMatching!$H:$H, AnglePowerMatching!$D:$D, "NaN") -> 3 | Q13: =NOT(OR(C13=0,D13=0)) -> TRUE | R13: =VALUE(_xlfn.TEXTBEFORE(A13, {"L","R"}, , , , A13)) -> 1029 | S13: =R13 & TEXT(B13, "yyyymmdd") -> 102920260107
... A84: 1034 | B84: 2025-12-15 | C84: 49.193548 | D84: 51.639344 | E84: 0 | F84: 1 | G84: 61 | H84: 63 | I84: 124 | J84: 123 | K84: 0 | L84: 0.81300813 | M84: 0.19740984 | N84: 0.18620635 | O84: =_xlfn.XLOOKUP(S84, AnglePowerMatching!$H:$H, AnglePowerMatching!$C:$C, "NaN") -> 66 | P84: =_xlfn.XLOOKUP(S84, AnglePowerMatching!$H:$H, AnglePowerMatching!$D:$D, "NaN") -> 3 masker | Q84: =NOT(OR(C84=0,D84=0)) -> TRUE | R84: =VALUE(_xlfn.TEXTBEFORE(A84, {"L","R"}, , , , A84)) -> 1034 | S84: =R84 & TEXT(B84, "yyyymmdd") -> 103420251215
A85: 1034 | B85: 2025-12-16 | C85: 0 | E85: 119 | F85: 120 | G85: 0 | H85: 0 | I85: 120 | J85: 120 | K85: 99.166667 | L85: 100 | O85: =_xlfn.XLOOKUP(S85, AnglePowerMatching!$H:$H, AnglePowerMatching!$C:$C, "NaN") -> NaN | P85: =_xlfn.XLOOKUP(S85, AnglePowerMatching!$H:$H, AnglePowerMatching!$D:$D, "NaN") -> NaN | Q85: =NOT(OR(C85=0,D85=0)) -> FALSE | R85: =VALUE(_xlfn.TEXTBEFORE(A85, {"L","R"}, , , , A85)) -> 1034 | S85: =R85 & TEXT(B85, "yyyymmdd") -> 103420251216
A86: 1034 | B86: 2025-12-17 | C86: 59.663866 | D86: 62.5 | E86: 1 | F86: 0 | G86: 71 | H86: 75 | I86: 120 | J86: 120 | K86: 0.83333333 | L86: 0 | M86: 0.22409859 | N86: 0.24790667 | O86: =_xlfn.XLOOKUP(S86, AnglePowerMatching!$H:$H, AnglePowerMatching!$C:$C, "NaN") -> 66 | P86: =_xlfn.XLOOKUP(S86, AnglePowerMatching!$H:$H, AnglePowerMatching!$D:$D, "NaN") -> 10 | Q86: =NOT(OR(C86=0,D86=0)) -> TRUE | R86: =VALUE(_xlfn.TEXTBEFORE(A86, {"L","R"}, , , , A86)) -> 1034 | S86: =R86 & TEXT(B86, "yyyymmdd") -> 103420251217
A87: 1034 | B87: 2025-12-18 | C87: 58.333333 | D87: 56.666667 | E87: 0 | F87: 0 | G87: 70 | H87: 68 | I87: 120 | J87: 120 | K87: 0 | L87: 0 | M87: 0.19927143 | N87: 0.18492647 | O87: =_xlfn.XLOOKUP(S87, AnglePowerMatching!$H:$H, AnglePowerMatching!$C:$C, "NaN") -> 66 | P87: =_xlfn.XLOOKUP(S87, AnglePowerMatching!$H:$H, AnglePowerMatching!$D:$D, "NaN") -> 3 | Q87: =NOT(OR(C87=0,D87=0)) -> TRUE | R87: =VALUE(_xlfn.TEXTBEFORE(A87, {"L","R"}, , , , A87)) -> 1034 | S87: =R87 & TEXT(B87, "yyyymmdd") -> 103420251218
A88: 1034 | B88: 2025-12-31 | C88: 52.205882 | D88: 50.735294 | E88: 0 | F88: 0 | G88: 71 | H88: 69 | I88: 136 | J88: 136 | K88: 0 | L88: 0 | M88: 0.20602817 | N88: 0.1906087 | O88: =_xlfn.XLOOKUP(S88, AnglePowerMatching!$H:$H, AnglePowerMatching!$C:$C, "NaN") -> 66 | P88: =_xlfn.XLOOKUP(S88, AnglePowerMatching!$H:$H, AnglePowerMatching!$D:$D, "NaN") -> 5 masker | Q88: =NOT(OR(C88=0,D88=0)) -> TRUE | R88: =VALUE(_xlfn.TEXTBEFORE(A88, {"L","R"}, , , , A88)) -> 1034 | S88: =R88 & TEXT(B88, "yyyymmdd") -> 103420251231
A89: 1034 | B89: 2026-01-13 | C89: 61.666667 | D89: 61.016949 | E89: 0 | F89: 2 | G89: 74 | H89: 72 | I89: 120 | J89: 120 | K89: 0 | L89: 1.6666667 | M89: 0.28716216 | N89: 0.28869444 | O89: =_xlfn.XLOOKUP(S89, AnglePowerMatching!$H:$H, AnglePowerMatching!$C:$C, "NaN") -> 66 | P89: =_xlfn.XLOOKUP(S89, AnglePowerMatching!$H:$H, AnglePowerMatching!$D:$D, "NaN") -> 3 masker | Q89: =NOT(OR(C89=0,D89=0)) -> TRUE | R89: =VALUE(_xlfn.TEXTBEFORE(A89, {"L","R"}, , , , A89)) -> 1034 | S89: =R89 & TEXT(B89, "yyyymmdd") -> 103420260113
A90: 1034 | B90: 2026-01-14 | C90: 49.586777 | D90: 59.166667 | E90: 0 | F90: 0 | G90: 60 | H90: 71 | I90: 121 | J90: 120 | K90: 0 | L90: 0 | M90: 0.19216667 | N90: 0.21511268 | O90: =_xlfn.XLOOKUP(S90, AnglePowerMatching!$H:$H, AnglePowerMatching!$C:$C, "NaN") -> 66 | P90: =_xlfn.XLOOKUP(S90, AnglePowerMatching!$H:$H, AnglePowerMatching!$D:$D, "NaN") -> 5 masker | Q90: =NOT(OR(C90=0,D90=0)) -> TRUE | R90: =VALUE(_xlfn.TEXTBEFORE(A90, {"L","R"}, , , , A90)) -> 1034 | S90: =R90 & TEXT(B90, "yyyymmdd") -> 103420260114
A91: 9450L | B91: 2025-08-18 | C91: 76.470588 | D91: 65.833333 | E91: 1 | F91: 0 | G91: 91 | H91: 79 | I91: 120 | J91: 120 | K91: 0.83333333 | L91: 0 | M91: 0.2632967 | N91: 0.24758228 | O91: =_xlfn.XLOOKUP(S91, AnglePowerMatching!$H:$H, AnglePowerMatching!$C:$C, "NaN") -> NaN | P91: =_xlfn.XLOOKUP(S91, AnglePowerMatching!$H:$H, AnglePowerMatching!$D:$D, "NaN") -> NaN | Q91: =NOT(OR(C91=0,D91=0)) -> TRUE | R91: =VALUE(_xlfn.TEXTBEFORE(A91, {"L","R"}, , , , A91)) -> 9450 | S91: =R91 & TEXT(B91, "yyyymmdd") -> 945020250818
A92: 948L | B92: 2025-07-24 | D92: 0 | E92: 0 | F92: 5 | G92: 0 | H92: 0 | I92: 0 | J92: 6 | K92: 0 | L92: 83.333333 | O92: =_xlfn.XLOOKUP(S92, AnglePowerMatching!$H:$H, AnglePowerMatching!$C:$C, "NaN") -> NaN | P92: =_xlfn.XLOOKUP(S92, AnglePowerMatching!$H:$H, AnglePowerMatching!$D:$D, "NaN") -> NaN | Q92: =NOT(OR(C92=0,D92=0)) -> FALSE | R92: =VALUE(_xlfn.TEXTBEFORE(A92, {"L","R"}, , , , A92)) -> 948 | S92: =R92 & TEXT(B92, "yyyymmdd") -> 94820250724
A93: 948L | B93: 2025-07-24 | D93: 0 | E93: 0 | F93: 5 | G93: 0 | H93: 0 | I93: 0 | J93: 6 | K93: 0 | L93: 83.333333 | O93: =_xlfn.XLOOKUP(S93, AnglePowerMatching!$H:$H, AnglePowerMatching!$C:$C, "NaN") -> NaN | P93: =_xlfn.XLOOKUP(S93, AnglePowerMatching!$H:$H, AnglePowerMatching!$D:$D, "NaN") -> NaN | Q93: =NOT(OR(C93=0,D93=0)) -> FALSE | R93: =VALUE(_xlfn.TEXTBEFORE(A93, {"L","R"}, , , , A93)) -> 948 | S93: =R93 & TEXT(B93, "yyyymmdd") -> 94820250724
A94: 948L | B94: 2025-07-24 | D94: 42.857143 | E94: 0 | F94: 1 | G94: 0 | H94: 6 | I94: 0 | J94: 15 | K94: 0 | L94: 6.6666667 | N94: 0.53583333 | O94: =_xlfn.XLOOKUP(S94, AnglePowerMatching!$H:$H, AnglePowerMatching!$C:$C, "NaN") -> NaN | P94: =_xlfn.XLOOKUP(S94, AnglePowerMatching!$H:$H, AnglePowerMatching!$D:$D, "NaN") -> NaN | Q94: =NOT(OR(C94=0,D94=0)) -> FALSE | R94: =VALUE(_xlfn.TEXTBEFORE(A94, {"L","R"}, , , , A94)) -> 948 | S94: =R94 & TEXT(B94, "yyyymmdd") -> 94820250724
A95: 948L | B95: 2025-07-25 | C95: 0 | D95: 100 | E95: 0 | F95: 0 | G95: 0 | H95: 2 | I95: 1 | J95: 2 | K95: 0 | L95: 0 | N95: 0.496 | O95: =_xlfn.XLOOKUP(S95, AnglePowerMatching!$H:$H, AnglePowerMatching!$C:$C, "NaN") -> 66 | P95: =_xlfn.XLOOKUP(S95, AnglePowerMatching!$H:$H, AnglePowerMatching!$D:$D, "NaN") -> 3 | Q95: =NOT(OR(C95=0,D95=0)) -> FALSE | R95: =VALUE(_xlfn.TEXTBEFORE(A95, {"L","R"}, , , , A95)) -> 948 | S95: =R95 & TEXT(B95, "yyyymmdd") -> 94820250725
A96: 948L | B96: 2025-07-25 | C96: 88.372093 | D96: 90.217391 | E96: 8 | F96: 2 | G96: 76 | H96: 83 | I96: 94 | J96: 94 | K96: 8.5106383 | L96: 2.1276596 | M96: 0.43493421 | N96: 0.40443373 | O96: =_xlfn.XLOOKUP(S96, AnglePowerMatching!$H:$H, AnglePowerMatching!$C:$C, "NaN") -> 66 | P96: =_xlfn.XLOOKUP(S96, AnglePowerMatching!$H:$H, AnglePowerMatching!$D:$D, "NaN") -> 3 | Q96: =NOT(OR(C96=0,D96=0)) -> TRUE | R96: =VALUE(_xlfn.TEXTBEFORE(A96, {"L","R"}, , , , A96)) -> 948 | S96: =R96 & TEXT(B96, "yyyymmdd") -> 94820250725
A97: 948L | B97: 2025-07-26 | C97: 91.304348 | D97: 86.486486 | E97: 9 | F97: 14 | G97: 105 | H97: 96 | I97: 124 | J97: 125 | K97: 7.2580645 | L97: 11.2 | M97: 0.37724762 | N97: 0.46075 | O97: =_xlfn.XLOOKUP(S97, AnglePowerMatching!$H:$H, AnglePowerMatching!$C:$C, "NaN") -> NaN | P97: =_xlfn.XLOOKUP(S97, AnglePowerMatching!$H:$H, AnglePowerMatching!$D:$D, "NaN") -> NaN | Q97: =NOT(OR(C97=0,D97=0)) -> TRUE | R97: =VALUE(_xlfn.TEXTBEFORE(A97, {"L","R"}, , , , A97)) -> 948 | S97: =R97 & TEXT(B97, "yyyymmdd") -> 94820250726
A98: 948L | B98: 2025-07-27 | C98: 50 | D98: 50 | E98: 0 | F98: 0 | G98: 2 | H98: 2 | I98: 4 | J98: 4 | K98: 0 | L98: 0 | M98: 0.188 | N98: 0.387 | O98: =_xlfn.XLOOKUP(S98, AnglePowerMatching!$H:$H, AnglePowerMatching!$C:$C, "NaN") -> 66 | P98: =_xlfn.XLOOKUP(S98, AnglePowerMatching!$H:$H, AnglePowerMatching!$D:$D, "NaN") -> 5 | Q98: =NOT(OR(C98=0,D98=0)) -> TRUE | R98: =VALUE(_xlfn.TEXTBEFORE(A98, {"L","R"}, , , , A98)) -> 948 | S98: =R98 & TEXT(B98, "yyyymmdd") -> 94820250727
A99: 948L | B99: 2025-07-27 | C99: 87.826087 | D99: 89.565217 | E99: 0 | F99: 0 | G99: 101 | H99: 103 | I99: 115 | J99: 115 | K99: 0 | L99: 0 | M99: 0.28676238 | N99: 0.28343689 | O99: =_xlfn.XLOOKUP(S99, AnglePowerMatching!$H:$H, AnglePowerMatching!$C:$C, "NaN") -> 66 | P99: =_xlfn.XLOOKUP(S99, AnglePowerMatching!$H:$H, AnglePowerMatching!$D:$D, "NaN") -> 5 | Q99: =NOT(OR(C99=0,D99=0)) -> TRUE | R99: =VALUE(_xlfn.TEXTBEFORE(A99, {"L","R"}, , , , A99)) -> 948 | S99: =R99 & TEXT(B99, "yyyymmdd") -> 94820250727
A100: 948L | B100: 2025-07-28 | C100: 100 | D100: 50 | E100: 0 | F100: 0 | G100: 1 | H100: 1 | I100: 1 | J100: 2 | K100: 0 | L100: 0 | M100: 0.476 | N100: 0.383 | O100: =_xlfn.XLOOKUP(S100, AnglePowerMatching!$H:$H, AnglePowerMatching!$C:$C, "NaN") -> 66 | P100: =_xlfn.XLOOKUP(S100, AnglePowerMatching!$H:$H, AnglePowerMatching!$D:$D, "NaN") -> 10 | Q100: =NOT(OR(C100=0,D100=0)) -> TRUE | R100: =VALUE(_xlfn.TEXTBEFORE(A100, {"L","R"}, , , , A100)) -> 948 | S100: =R100 & TEXT(B100, "yyyymmdd") -> 94820250728
A101: 948L | B101: 2025-07-28 | C101: 100 | D101: 100 | E101: 0 | F101: 0 | G101: 1 | H101: 2 | I101: 1 | J101: 2 | K101: 0 | L101: 0 | M101: 0.575 | N101: 0.683 | O101: =_xlfn.XLOOKUP(S101, AnglePowerMatching!$H:$H, AnglePowerMatching!$C:$C, "NaN") -> 66 | P101: =_xlfn.XLOOKUP(S101, AnglePowerMatching!$H:$H, AnglePowerMatching!$D:$D, "NaN") -> 10 | Q101: =NOT(OR(C101=0,D101=0)) -> TRUE | R101: =VALUE(_xlfn.TEXTBEFORE(A101, {"L","R"}, , , , A101)) -> 948 | S101: =R101 & TEXT(B101, "yyyymmdd") -> 94820250728
A102: 948L | B102: 2025-07-28 | C102: 100 | D102: 66.666667 | E102: 1 | F102: 0 | G102: 5 | H102: 4 | I102: 6 | J102: 6 | K102: 16.666667 | L102: 0 | M102: 0.4664 | N102: 0.48775 | O102: =_xlfn.XLOOKUP(S102, AnglePowerMatching!$H:$H, AnglePowerMatching!$C:$C, "NaN") -> 66 | P102: =_xlfn.XLOOKUP(S102, AnglePowerMatching!$H:$H, AnglePowerMatching!$D:$D, "NaN") -> 10 | Q102: =NOT(OR(C102=0,D102=0)) -> TRUE | R102: =VALUE(_xlfn.TEXTBEFORE(A102, {"L","R"}, , , , A102)) -> 948 | S102: =R102 & TEXT(B102, "yyyymmdd") -> 94820250728
A103: 948L | B103: 2025-07-28 | C103: 93.814433 | D103: 88.77551 | E103: 23 | F103: 22 | G103: 91 | H103: 87 | I103: 120 | J103: 120 | K103: 19.166667 | L103: 18.333333 | M103: 0.54502198 | N103: 0.55297701 | O103: =_xlfn.XLOOKUP(S103, AnglePowerMatching!$H:$H, AnglePowerMatching!$C:$C, "NaN") -> 66 | P103: =_xlfn.XLOOKUP(S103, AnglePowerMatching!$H:$H, AnglePowerMatching!$D:$D, "NaN") -> 10 | Q103: =NOT(OR(C103=0,D103=0)) -> TRUE | R103: =VALUE(_xlfn.TEXTBEFORE(A103, {"L","R"}, , , , A103)) -> 948 | S103: =R103 & TEXT(B103, "yyyymmdd") -> 94820250728
A104: 948L | B104: 2025-07-29 | C104: 84.931507 | D104: 89.74359 | E104: 47 | F104: 42 | G104: 62 | H104: 70 | I104: 120 | J104: 120 | K104: 39.166667 | L104: 35 | M104: 0.61246774 | N104: 0.63437143 | O104: =_xlfn.XLOOKUP(S104, AnglePowerMatching!$H:$H, AnglePowerMatching!$C:$C, "NaN") -> 66 | P104: =_xlfn.XLOOKUP(S104, AnglePowerMatching!$H:$H, AnglePowerMatching!$D:$D, "NaN") -> 3 | Q104: =NOT(OR(C104=0,D104=0)) -> TRUE | R104: =VALUE(_xlfn.TEXTBEFORE(A104, {"L","R"}, , , , A104)) -> 948 | S104: =R104 & TEXT(B104, "yyyymmdd") -> 94820250729
A105: 948L | B105: 2025-07-30 | D105: 0 | E105: 0 | F105: 1 | G105: 0 | H105: 0 | I105: 0 | J105: 2 | K105: 0 | L105: 50 | O105: =_xlfn.XLOOKUP(S105, AnglePowerMatching!$H:$H, AnglePowerMatching!$C:$C, "NaN") -> 90 | P105: =_xlfn.XLOOKUP(S105, AnglePowerMatching!$H:$H, AnglePowerMatching!$D:$D, "NaN") -> 3 | Q105: =NOT(OR(C105=0,D105=0)) -> FALSE | R105: =VALUE(_xlfn.TEXTBEFORE(A105, {"L","R"}, , , , A105)) -> 948 | S105: =R105 & TEXT(B105, "yyyymmdd") -> 94820250730
A106: 948L | B106: 2025-07-30 | C106: 0 | E106: 1 | F106: 2 | G106: 0 | H106: 0 | I106: 2 | J106: 2 | K106: 50 | L106: 100 | O106: =_xlfn.XLOOKUP(S106, AnglePowerMatching!$H:$H, AnglePowerMatching!$C:$C, "NaN") -> 90 | P106: =_xlfn.XLOOKUP(S106, AnglePowerMatching!$H:$H, AnglePowerMatching!$D:$D, "NaN") -> 3 | Q106: =NOT(OR(C106=0,D106=0)) -> FALSE | R106: =VALUE(_xlfn.TEXTBEFORE(A106, {"L","R"}, , , , A106)) -> 948 | S106: =R106 & TEXT(B106, "yyyymmdd") -> 94820250730
A107: 948L | B107: 2025-07-30 | C107: 91.780822 | D107: 89.534884 | E107: 42 | F107: 30 | G107: 67 | H107: 77 | I107: 115 | J107: 116 | K107: 36.521739 | L107: 25.862069 | M107: 0.51428358 | N107: 0.53480519 | O107: =_xlfn.XLOOKUP(S107, AnglePowerMatching!$H:$H, AnglePowerMatching!$C:$C, "NaN") -> 90 | P107: =_xlfn.XLOOKUP(S107, AnglePowerMatching!$H:$H, AnglePowerMatching!$D:$D, "NaN") -> 3 | Q107: =NOT(OR(C107=0,D107=0)) -> TRUE | R107: =VALUE(_xlfn.TEXTBEFORE(A107, {"L","R"}, , , , A107)) -> 948 | S107: =R107 & TEXT(B107, "yyyymmdd") -> 94820250730
A108: 948L | B108: 2025-07-31 | C108: 83.478261 | D108: 87.610619 | E108: 5 | F108: 7 | G108: 96 | H108: 99 | I108: 120 | J108: 120 | K108: 4.1666667 | L108: 5.8333333 | M108: 0.41176042 | N108: 0.43931313 | O108: =_xlfn.XLOOKUP(S108, AnglePowerMatching!$H:$H, AnglePowerMatching!$C:$C, "NaN") -> 90 | P108: =_xlfn.XLOOKUP(S108, AnglePowerMatching!$H:$H, AnglePowerMatching!$D:$D, "NaN") -> 5 | Q108: =NOT(OR(C108=0,D108=0)) -> TRUE | R108: =VALUE(_xlfn.TEXTBEFORE(A108, {"L","R"}, , , , A108)) -> 948 | S108: =R108 & TEXT(B108, "yyyymmdd") -> 94820250731
A109: 948L | B109: 2025-08-01 | C109: 96.039604 | D109: 91.818182 | E109: 29 | F109: 21 | G109: 97 | H109: 101 | I109: 130 | J109: 131 | K109: 22.307692 | L109: 16.030534 | M109: 0.51113402 | N109: 0.49015842 | O109: =_xlfn.XLOOKUP(S109, AnglePowerMatching!$H:$H, AnglePowerMatching!$C:$C, "NaN") -> 90 | P109: =_xlfn.XLOOKUP(S109, AnglePowerMatching!$H:$H, AnglePowerMatching!$D:$D, "NaN") -> 10 | Q109: =NOT(OR(C109=0,D109=0)) -> TRUE | R109: =VALUE(_xlfn.TEXTBEFORE(A109, {"L","R"}, , , , A109)) -> 948 | S109: =R109 & TEXT(B109, "yyyymmdd") -> 94820250801
A110: 948L | B110: 2025-08-02 | C110: 92.537313 | D110: 96.240602 | E110: 0 | F110: 2 | G110: 124 | H110: 128 | I110: 134 | J110: 135 | K110: 0 | L110: 1.4814815 | M110: 0.38116129 | N110: 0.37492969 | O110: =_xlfn.XLOOKUP(S110, AnglePowerMatching!$H:$H, AnglePowerMatching!$C:$C, "NaN") -> NaN | P110: =_xlfn.XLOOKUP(S110, AnglePowerMatching!$H:$H, AnglePowerMatching!$D:$D, "NaN") -> NaN | Q110: =NOT(OR(C110=0,D110=0)) -> TRUE | R110: =VALUE(_xlfn.TEXTBEFORE(A110, {"L","R"}, , , , A110)) -> 948 | S110: =R110 & TEXT(B110, "yyyymmdd") -> 94820250802
...

Sheet AnglePowerMatching
A1: ID | B1: Date | C1: Angle | D1: Power | G1: CleanID | H1: SEARCH | K1: Old:
A2: 1029R | B2: 45983 | C2: 66 | D2: 3 | G2: =VALUE(_xlfn.TEXTBEFORE(A2, {"L","R"}, , , , A2)) -> 1029 | H2: =LEFT(A2, LEN(A2)-1) & TEXT(B2, "yyyymmdd") -> 102920251122 | K2: Angle Formula: =XLOOKUP(A2 & D2, AnglePowerMatching!A:A & AnglePowerMatching!B:B, AnglePowerMatching!C:C, "Not Found")
A3: 1029R | B3: 45984 | C3: 66 | D3: 5 | G3: =VALUE(_xlfn.TEXTBEFORE(A3, {"L","R"}, , , , A3)) -> 1029 | H3: =LEFT(A3, LEN(A3)-1) & TEXT(B3, "yyyymmdd") -> 102920251123 | K3: Power Formula: =XLOOKUP(A2 & D2, AnglePowerMatching!A:A & AnglePowerMatching!B:B, AnglePowerMatching!D:D, "Not Found")
A4: 1029R | B4: 45985 | C4: 66 | D4: 10 | G4: =VALUE(_xlfn.TEXTBEFORE(A4, {"L","R"}, , , , A4)) -> 1029 | H4: =LEFT(A4, LEN(A4)-1) & TEXT(B4, "yyyymmdd") -> 102920251124
A5: 1029R | B5: 46003 | C5: 90 | D5: 3 | G5: =VALUE(_xlfn.TEXTBEFORE(A5, {"L","R"}, , , , A5)) -> 1029 | H5: =LEFT(A5, LEN(A5)-1) & TEXT(B5, "yyyymmdd") -> 102920251212 | K5: With CleanID & Search:
A6: 1029R | B6: 46004 | C6: 90 | D6: 5 | G6: =VALUE(_xlfn.TEXTBEFORE(A6, {"L","R"}, , , , A6)) -> 1029 | H6: =LEFT(A6, LEN(A6)-1) & TEXT(B6, "yyyymmdd") -> 102920251213 | K6: Angle Formula: =XLOOKUP(S2, AnglePowerMatching!$H:$H, AnglePowerMatching!$C:$C, "NaN")
A7: 1029R | B7: 46006 | C7: 90 | D7: 10 | G7: =VALUE(_xlfn.TEXTBEFORE(A7, {"L","R"}, , , , A7)) -> 1029 | H7: =LEFT(A7, LEN(A7)-1) & TEXT(B7, "yyyymmdd") -> 102920251215 | K7: Power Formula: =XLOOKUP(S2, AnglePowerMatching!$H:$H, AnglePowerMatching!$D:$D, "NaN")
A8: 1029R | B8: 46007 | C8: 90 | D8: 10 | G8: =VALUE(_xlfn.TEXTBEFORE(A8, {"L","R"}, , , , A8)) -> 1029 | H8: =LEFT(A8, LEN(A8)-1) & TEXT(B8, "yyyymmdd") -> 102920251216
A9: 1029R | B9: 46008 | C9: 90 | D9: 10 | G9: =VALUE(_xlfn.TEXTBEFORE(A9, {"L","R"}, , , , A9)) -> 1029 | H9: =LEFT(A9, LEN(A9)-1) & TEXT(B9, "yyyymmdd") -> 102920251217 | K9: Not updated (excludes new data files)
A10: 1029R | B10: 46009 | C10: 90 | D10: 5 | G10: =VALUE(_xlfn.TEXTBEFORE(A10, {"L","R"}, , , , A10)) -> 1029 | H10: =LEFT(A10, LEN(A10)-1) & TEXT(B10, "yyyymmdd") -> 102920251218
A11: 1029R | B11: 46021 | C11: 90 | D11: 10 | G11: =VALUE(_xlfn.TEXTBEFORE(A11, {"L","R"}, , , , A11)) -> 1029 | H11: =LEFT(A11, LEN(A11)-1) & TEXT(B11, "yyyymmdd") -> 102920251230 | K11: Visualize: =NOT(OR(C2=0,D2=0))
A12: 1029R | B12: 46022 | C12: 90 | D12: 5 | G12: =VALUE(_xlfn.TEXTBEFORE(A12, {"L","R"}, , , , A12)) -> 1029 | H12: =LEFT(A12, LEN(A12)-1) & TEXT(B12, "yyyymmdd") -> 102920251231
A13: 1029R | B13: 46029 | C13: 35 | D13: 3 | G13: =VALUE(_xlfn.TEXTBEFORE(A13, {"L","R"}, , , , A13)) -> 1029 | H13: =LEFT(A13, LEN(A13)-1) & TEXT(B13, "yyyymmdd") -> 102920260107
A14: 1029R | B14: 46030 | C14: 35 | D14: 5 | G14: =VALUE(_xlfn.TEXTBEFORE(A14, {"L","R"}, , , , A14)) -> 1029 | H14: =LEFT(A14, LEN(A14)-1) & TEXT(B14, "yyyymmdd") -> 102920260108
A15: 1029R | B15: 46031 | C15: 35 | D15: 10 | G15: =VALUE(_xlfn.TEXTBEFORE(A15, {"L","R"}, , , , A15)) -> 1029 | H15: =LEFT(A15, LEN(A15)-1) & TEXT(B15, "yyyymmdd") -> 102920260109
A16: 1029R | B16: 46032 | C16: 35 | D16: 10 | G16: =VALUE(_xlfn.TEXTBEFORE(A16, {"L","R"}, , , , A16)) -> 1029 | H16: =LEFT(A16, LEN(A16)-1) & TEXT(B16, "yyyymmdd") -> 102920260110
A17: 1029R | B17: 46044 | C17: 26 | D17: 3 | G17: =VALUE(_xlfn.TEXTBEFORE(A17, {"L","R"}, , , , A17)) -> 1029 | H17: =LEFT(A17, LEN(A17)-1) & TEXT(B17, "yyyymmdd") -> 102920260122
A18: 1029R | B18: 46045 | C18: 26 | D18: 5 | G18: =VALUE(_xlfn.TEXTBEFORE(A18, {"L","R"}, , , , A18)) -> 1029 | H18: =LEFT(A18, LEN(A18)-1) & TEXT(B18, "yyyymmdd") -> 102920260123
A19: 1029R | B19: 46051 | C19: 16 | D19: 3 | G19: =VALUE(_xlfn.TEXTBEFORE(A19, {"L","R"}, , , , A19)) -> 1029 | H19: =LEFT(A19, LEN(A19)-1) & TEXT(B19, "yyyymmdd") -> 102920260129
A20: 1029R | B20: 46052 | C20: 16 | D20: 5 | G20: =VALUE(_xlfn.TEXTBEFORE(A20, {"L","R"}, , , , A20)) -> 1029 | H20: =LEFT(A20, LEN(A20)-1) & TEXT(B20, "yyyymmdd") -> 102920260130
A21: 1029R | B21: 46053 | C21: 16 | D21: 10 | G21: =VALUE(_xlfn.TEXTBEFORE(A21, {"L","R"}, , , , A21)) -> 1029 | H21: =LEFT(A21, LEN(A21)-1) & TEXT(B21, "yyyymmdd") -> 102920260131
A22: 1030R | B22: 45945 | C22: 66 | D22: 3 | G22: =VALUE(_xlfn.TEXTBEFORE(A22, {"L","R"}, , , , A22)) -> 1030 | H22: =LEFT(A22, LEN(A22)-1) & TEXT(B22, "yyyymmdd") -> 103020251015
A23: 1030R | B23: 45946 | C23: 66 | D23: 5 | G23: =VALUE(_xlfn.TEXTBEFORE(A23, {"L","R"}, , , , A23)) -> 1030 | H23: =LEFT(A23, LEN(A23)-1) & TEXT(B23, "yyyymmdd") -> 103020251016
... A38: 1030R | B38: 45980 | C38: 16 | D38: 10 | G38: =VALUE(_xlfn.TEXTBEFORE(A38, {"L","R"}, , , , A38)) -> 1030 | H38: =LEFT(A38, LEN(A38)-1) & TEXT(B38, "yyyymmdd") -> 103020251119
A39: 1030R | B39: 46006 | C39: 66 | D39: 3 masker | G39: =VALUE(_xlfn.TEXTBEFORE(A39, {"L","R"}, , , , A39)) -> 1030 | H39: =LEFT(A39, LEN(A39)-1) & TEXT(B39, "yyyymmdd") -> 103020251215
A40: 1030R | B40: 46008 | C40: 66 | D40: 3 masker | G40: =VALUE(_xlfn.TEXTBEFORE(A40, {"L","R"}, , , , A40)) -> 1030 | H40: =LEFT(A40, LEN(A40)-1) & TEXT(B40, "yyyymmdd") -> 103020251217
A41: 1030R | B41: 46009 | C41: 66 | D41: 3 masker | G41: =VALUE(_xlfn.TEXTBEFORE(A41, {"L","R"}, , , , A41)) -> 1030 | H41: =LEFT(A41, LEN(A41)-1) & TEXT(B41, "yyyymmdd") -> 103020251218
A42: 1030R | B42: 46021 | C42: 66 | D42: 10 | G42: =VALUE(_xlfn.TEXTBEFORE(A42, {"L","R"}, , , , A42)) -> 1030 | H42: =LEFT(A42, LEN(A42)-1) & TEXT(B42, "yyyymmdd") -> 103020251230
A43: 1031L | B43: 45983 | C43: 66 | D43: 3 | G43: =VALUE(_xlfn.TEXTBEFORE(A43, {"L","R"}, , , , A43)) -> 1031 | H43: =LEFT(A43, LEN(A43)-1) & TEXT(B43, "yyyymmdd") -> 103120251122
A44: 1031L | B44: 45984 | C44: 66 | D44: 5 | G44: =VALUE(_xlfn.TEXTBEFORE(A44, {"L","R"}, , , , A44)) -> 1031 | H44: =LEFT(A44, LEN(A44)-1) & TEXT(B44, "yyyymmdd") -> 103120251123
A45: 1031L | B45: 45985 | C45: 66 | D45: 10 | G45: =VALUE(_xlfn.TEXTBEFORE(A45, {"L","R"}, , , , A45)) -> 1031 | H45: =LEFT(A45, LEN(A45)-1) & TEXT(B45, "yyyymmdd") -> 103120251124
A46: 1031L | B46: 46003 | C46: 90 | D46: 3 | G46: =VALUE(_xlfn.TEXTBEFORE(A46, {"L","R"}, , , , A46)) -> 1031 | H46: =LEFT(A46, LEN(A46)-1) & TEXT(B46, "yyyymmdd") -> 103120251212
A47: 1031L | B47: 46004 | C47: 90 | D47: 5 | G47: =VALUE(_xlfn.TEXTBEFORE(A47, {"L","R"}, , , , A47)) -> 1031 | H47: =LEFT(A47, LEN(A47)-1) & TEXT(B47, "yyyymmdd") -> 103120251213
A48: 1031L | B48: 46006 | C48: 90 | D48: 10 | G48: =VALUE(_xlfn.TEXTBEFORE(A48, {"L","R"}, , , , A48)) -> 1031 | H48: =LEFT(A48, LEN(A48)-1) & TEXT(B48, "yyyymmdd") -> 103120251215
A49: 1031L | B49: 46007 | C49: 90 | D49: 10 | G49: =VALUE(_xlfn.TEXTBEFORE(A49, {"L","R"}, , , , A49)) -> 1031 | H49: =LEFT(A49, LEN(A49)-1) & TEXT(B49, "yyyymmdd") -> 103120251216
A50: 1031L | B50: 46008 | C50: 90 | D50: 10 | G50: =VALUE(_xlfn.TEXTBEFORE(A50, {"L","R"}, , , , A50)) -> 1031 | H50: =LEFT(A50, LEN(A50)-1) & TEXT(B50, "yyyymmdd") -> 103120251217
A51: 1031L | B51: 46009 | C51: 90 | D51: 5 | G51: =VALUE(_xlfn.TEXTBEFORE(A51, {"L","R"}, , , , A51)) -> 1031 | H51: =LEFT(A51, LEN(A51)-1) & TEXT(B51, "yyyymmdd") -> 103120251218
A52: 1031L | B52: 46031 | C52: 35 | D52: 3 | G52: =VALUE(_xlfn.TEXTBEFORE(A52, {"L","R"}, , , , A52)) -> 1031 | H52: =LEFT(A52, LEN(A52)-1) & TEXT(B52, "yyyymmdd") -> 103120260109
A53: 1031L | B53: 46032 | C53: 35 | D53: 5 | G53: =VALUE(_xlfn.TEXTBEFORE(A53, {"L","R"}, , , , A53)) -> 1031 | H53: =LEFT(A53, LEN(A53)-1) & TEXT(B53, "yyyymmdd") -> 103120260110
... A79: 1034R | B79: 45980 | C79: 16 | D79: 10 | G79: =VALUE(_xlfn.TEXTBEFORE(A79, {"L","R"}, , , , A79)) -> 1034 | H79: =LEFT(A79, LEN(A79)-1) & TEXT(B79, "yyyymmdd") -> 103420251119
...

Sheet dupe
A1: ID | B1: Date | C1: AccuracyLaser | D1: AccuracyNonLaser | E1: OmissionsLaser | F1: OmissionsNonLaser | G1: LaserReward | H1: NonLaserReward | I1: LaserTrials | J1: NonLaserTrials | K1: oLaserPercent | L1: oNonLaserPercent | M1: LatencyLaser | N1: LatencyNonLaser | O1: Angle | P1: Power | Q1: Visualize | R1: CleanID | S1: SEARCH
A2: 1029 | B2: 2025-11-22 | C2: 54.166667 | D2: 55 | E2: 0 | F2: 0 | G2: 65 | H2: 66 | I2: 120 | J2: 120 | K2: 0 | L2: 0 | M2: 0.18281538 | N2: 0.19430303 | O2: =_xlfn.XLOOKUP(S2, AnglePowerMatching!$H:$H, AnglePowerMatching!$C:$C, "NaN") -> 66 | P2: =_xlfn.XLOOKUP(S2, AnglePowerMatching!$H:$H, AnglePowerMatching!$D:$D, "NaN") -> 3 | Q2: =NOT(OR(C2=0,D2=0)) -> TRUE | R2: =VALUE(_xlfn.TEXTBEFORE(A2, {"L","R"}, , , , A2)) -> 1029 | S2: =R2 & TEXT(B2, "yyyymmdd") -> 102920251122
A3: 1029 | B3: 2025-11-23 | C3: 53.333333 | D3: 51.666667 | E3: 0 | F3: 0 | G3: 64 | H3: 62 | I3: 120 | J3: 120 | K3: 0 | L3: 0 | M3: 0.27225 | N3: 0.28053226 | O3: =_xlfn.XLOOKUP(S3, AnglePowerMatching!$H:$H, AnglePowerMatching!$C:$C, "NaN") -> 66 | P3: =_xlfn.XLOOKUP(S3, AnglePowerMatching!$H:$H, AnglePowerMatching!$D:$D, "NaN") -> 5 | Q3: =NOT(OR(C3=0,D3=0)) -> TRUE | R3: =VALUE(_xlfn.TEXTBEFORE(A3, {"L","R"}, , , , A3)) -> 1029 | S3: =R3 & TEXT(B3, "yyyymmdd") -> 102920251123
A4: 1029 | B4: 2025-11-24 | C4: 51.666667 | D4: 46.666667 | E4: 0 | F4: 0 | G4: 62 | H4: 56 | I4: 120 | J4: 120 | K4: 0 | L4: 0 | M4: 0.29008065 | N4: 0.20426786 | O4: =_xlfn.XLOOKUP(S4, AnglePowerMatching!$H:$H, AnglePowerMatching!$C:$C, "NaN") -> 66 | P4: =_xlfn.XLOOKUP(S4, AnglePowerMatching!$H:$H, AnglePowerMatching!$D:$D, "NaN") -> 10 | Q4: =NOT(OR(C4=0,D4=0)) -> TRUE | R4: =VALUE(_xlfn.TEXTBEFORE(A4, {"L","R"}, , , , A4)) -> 1029 | S4: =R4 & TEXT(B4, "yyyymmdd") -> 102920251124
A5: 1029 | B5: 2025-12-12 | C5: 65.833333 | D5: 65.833333 | E5: 0 | F5: 0 | G5: 79 | H5: 79 | I5: 120 | J5: 120 | K5: 0 | L5: 0 | M5: 0.26475949 | N5: 0.24287342 | O5: =_xlfn.XLOOKUP(S5, AnglePowerMatching!$H:$H, AnglePowerMatching!$C:$C, "NaN") -> 90 | P5: =_xlfn.XLOOKUP(S5, AnglePowerMatching!$H:$H, AnglePowerMatching!$D:$D, "NaN") -> 3 | Q5: =NOT(OR(C5=0,D5=0)) -> TRUE | R5: =VALUE(_xlfn.TEXTBEFORE(A5, {"L","R"}, , , , A5)) -> 1029 | S5: =R5 & TEXT(B5, "yyyymmdd") -> 102920251212
A6: 1029 | B6: 2025-12-13 | C6: 82.5 | D6: 86.419753 | E6: 40 | F6: 39 | G6: 66 | H6: 70 | I6: 120 | J6: 120 | K6: 33.333333 | L6: 32.5 | M6: 0.42874242 | N6: 0.34355714 | O6: =_xlfn.XLOOKUP(S6, AnglePowerMatching!$H:$H, AnglePowerMatching!$C:$C, "NaN") -> 90 | P6: =_xlfn.XLOOKUP(S6, AnglePowerMatching!$H:$H, AnglePowerMatching!$D:$D, "NaN") -> 5 | Q6: =NOT(OR(C6=0,D6=0)) -> TRUE | R6: =VALUE(_xlfn.TEXTBEFORE(A6, {"L","R"}, , , , A6)) -> 1029 | S6: =R6 & TEXT(B6, "yyyymmdd") -> 102920251213
A7: 1029 | B7: 2025-12-15 | C7: 81.034483 | D7: 70.175439 | E7: 62 | F7: 63 | G7: 47 | H7: 40 | I7: 120 | J7: 120 | K7: 51.666667 | L7: 52.5 | M7: 0.96259574 | N7: 0.9585 | O7: =_xlfn.XLOOKUP(S7, AnglePowerMatching!$H:$H, AnglePowerMatching!$C:$C, "NaN") -> 90 | P7: =_xlfn.XLOOKUP(S7, AnglePowerMatching!$H:$H, AnglePowerMatching!$D:$D, "NaN") -> 10 | Q7: =NOT(OR(C7=0,D7=0)) -> TRUE | R7: =VALUE(_xlfn.TEXTBEFORE(A7, {"L","R"}, , , , A7)) -> 1029 | S7: =R7 & TEXT(B7, "yyyymmdd") -> 102920251215
A8: 1029 | B8: 2025-12-16 | C8: 36.595745 | D8: 36.820084 | E8: 5 | F8: 1 | G8: 86 | H8: 88 | I8: 240 | J8: 240 | K8: 2.0833333 | L8: 0.41666667 | M8: 0.30010465 | N8: 0.28431818 | O8: =_xlfn.XLOOKUP(S8, AnglePowerMatching!$H:$H, AnglePowerMatching!$C:$C, "NaN") -> 90 | P8: =_xlfn.XLOOKUP(S8, AnglePowerMatching!$H:$H, AnglePowerMatching!$D:$D, "NaN") -> 10 | Q8: =NOT(OR(C8=0,D8=0)) -> TRUE | R8: =VALUE(_xlfn.TEXTBEFORE(A8, {"L","R"}, , , , A8)) -> 1029 | S8: =R8 & TEXT(B8, "yyyymmdd") -> 102920251216
A9: 1029 | B9: 2025-12-17 | C9: 64.285714 | D9: 65.789474 | E9: 12 | F9: 11 | G9: 72 | H9: 75 | I9: 124 | J9: 125 | K9: 9.6774194 | L9: 8.8 | M9: 0.29847222 | N9: 0.25242667 | O9: =_xlfn.XLOOKUP(S9, AnglePowerMatching!$H:$H, AnglePowerMatching!$C:$C, "NaN") -> 90 | P9: =_xlfn.XLOOKUP(S9, AnglePowerMatching!$H:$H, AnglePowerMatching!$D:$D, "NaN") -> 10 | Q9: =NOT(OR(C9=0,D9=0)) -> TRUE | R9: =VALUE(_xlfn.TEXTBEFORE(A9, {"L","R"}, , , , A9)) -> 1029 | S9: =R9 & TEXT(B9, "yyyymmdd") -> 102920251217
A10: 1029 | B10: 2025-12-18 | C10: 62.608696 | D10: 55.555556 | E10: 5 | F10: 3 | G10: 72 | H10: 65 | I10: 120 | J10: 120 | K10: 4.1666667 | L10: 2.5 | M10: 0.26394444 | N10: 0.23587692 | O10: =_xlfn.XLOOKUP(S10, AnglePowerMatching!$H:$H, AnglePowerMatching!$C:$C, "NaN") -> 90 | P10: =_xlfn.XLOOKUP(S10, AnglePowerMatching!$H:$H, AnglePowerMatching!$D:$D, "NaN") -> 5 | Q10: =NOT(OR(C10=0,D10=0)) -> TRUE | R10: =VALUE(_xlfn.TEXTBEFORE(A10, {"L","R"}, , , , A10)) -> 1029 | S10: =R10 & TEXT(B10, "yyyymmdd") -> 102920251218
A11: 1029 | B11: 2025-12-30 | C11: 60.504202 | D11: 62.280702 | E11: 1 | F11: 6 | G11: 72 | H11: 71 | I11: 120 | J11: 120 | K11: 0.83333333 | L11: 5 | M11: 0.28647222 | N11: 0.2645493 | O11: =_xlfn.XLOOKUP(S11, AnglePowerMatching!$H:$H, AnglePowerMatching!$C:$C, "NaN") -> 90 | P11: =_xlfn.XLOOKUP(S11, AnglePowerMatching!$H:$H, AnglePowerMatching!$D:$D, "NaN") -> 10 | Q11: =NOT(OR(C11=0,D11=0)) -> TRUE | R11: =VALUE(_xlfn.TEXTBEFORE(A11, {"L","R"}, , , , A11)) -> 1029 | S11: =R11 & TEXT(B11, "yyyymmdd") -> 102920251230
A12: 1029 | B12: 2025-12-31 | C12: 73.684211 | D12: 76.229508 | E12: 22 | F12: 14 | G12: 84 | H12: 93 | I12: 136 | J12: 136 | K12: 16.176471 | L12: 10.294118 | M12: 0.28832143 | N12: 0.27991398 | O12: =_xlfn.XLOOKUP(S12, AnglePowerMatching!$H:$H, AnglePowerMatching!$C:$C, "NaN") -> 90 | P12: =_xlfn.XLOOKUP(S12, AnglePowerMatching!$H:$H, AnglePowerMatching!$D:$D, "NaN") -> 5 | Q12: =NOT(OR(C12=0,D12=0)) -> TRUE | R12: =VALUE(_xlfn.TEXTBEFORE(A12, {"L","R"}, , , , A12)) -> 1029 | S12: =R12 & TEXT(B12, "yyyymmdd") -> 102920251231
A13: 1029 | B13: 2026-01-07 | C13: 55.833333 | D13: 51.260504 | E13: 0 | F13: 1 | G13: 67 | H13: 61 | I13: 120 | J13: 120 | K13: 0 | L13: 0.83333333 | M13: 0.31301493 | N13: 0.26309836 | O13: =_xlfn.XLOOKUP(S13, AnglePowerMatching!$H:$H, AnglePowerMatching!$C:$C, "NaN") -> 35 | P13: =_xlfn.XLOOKUP(S13, AnglePowerMatching!$H:$H, AnglePowerMatching!$D:$D, "NaN") -> 3 | Q13: =NOT(OR(C13=0,D13=0)) -> TRUE | R13: =VALUE(_xlfn.TEXTBEFORE(A13, {"L","R"}, , , , A13)) -> 1029 | S13: =R13 & TEXT(B13, "yyyymmdd") -> 102920260107
... A84: 1034 | B84: 2025-12-15 | C84: 49.193548 | D84: 51.639344 | E84: 0 | F84: 1 | G84: 61 | H84: 63 | I84: 124 | J84: 123 | K84: 0 | L84: 0.81300813 | M84: 0.19740984 | N84: 0.18620635 | O84: =_xlfn.XLOOKUP(S84, AnglePowerMatching!$H:$H, AnglePowerMatching!$C:$C, "NaN") -> 66 | P84: =_xlfn.XLOOKUP(S84, AnglePowerMatching!$H:$H, AnglePowerMatching!$D:$D, "NaN") -> 3 masker | Q84: =NOT(OR(C84=0,D84=0)) -> TRUE | R84: =VALUE(_xlfn.TEXTBEFORE(A84, {"L","R"}, , , , A84)) -> 1034 | S84: =R84 & TEXT(B84, "yyyymmdd") -> 103420251215
A85: 1034 | B85: 2025-12-16 | C85: 0 | E85: 119 | F85: 120 | G85: 0 | H85: 0 | I85: 120 | J85: 120 | K85: 99.166667 | L85: 100 | O85: =_xlfn.XLOOKUP(S85, AnglePowerMatching!$H:$H, AnglePowerMatching!$C:$C, "NaN") -> NaN | P85: =_xlfn.XLOOKUP(S85, AnglePowerMatching!$H:$H, AnglePowerMatching!$D:$D, "NaN") -> NaN | Q85: =NOT(OR(C85=0,D85=0)) -> FALSE | R85: =VALUE(_xlfn.TEXTBEFORE(A85, {"L","R"}, , , , A85)) -> 1034 | S85: =R85 & TEXT(B85, "yyyymmdd") -> 103420251216
A86: 1034 | B86: 2025-12-17 | C86: 59.663866 | D86: 62.5 | E86: 1 | F86: 0 | G86: 71 | H86: 75 | I86: 120 | J86: 120 | K86: 0.83333333 | L86: 0 | M86: 0.22409859 | N86: 0.24790667 | O86: =_xlfn.XLOOKUP(S86, AnglePowerMatching!$H:$H, AnglePowerMatching!$C:$C, "NaN") -> 66 | P86: =_xlfn.XLOOKUP(S86, AnglePowerMatching!$H:$H, AnglePowerMatching!$D:$D, "NaN") -> 10 | Q86: =NOT(OR(C86=0,D86=0)) -> TRUE | R86: =VALUE(_xlfn.TEXTBEFORE(A86, {"L","R"}, , , , A86)) -> 1034 | S86: =R86 & TEXT(B86, "yyyymmdd") -> 103420251217
A87: 1034 | B87: 2025-12-18 | C87: 58.333333 | D87: 56.666667 | E87: 0 | F87: 0 | G87: 70 | H87: 68 | I87: 120 | J87: 120 | K87: 0 | L87: 0 | M87: 0.19927143 | N87: 0.18492647 | O87: =_xlfn.XLOOKUP(S87, AnglePowerMatching!$H:$H, AnglePowerMatching!$C:$C, "NaN") -> 66 | P87: =_xlfn.XLOOKUP(S87, AnglePowerMatching!$H:$H, AnglePowerMatching!$D:$D, "NaN") -> 3 | Q87: =NOT(OR(C87=0,D87=0)) -> TRUE | R87: =VALUE(_xlfn.TEXTBEFORE(A87, {"L","R"}, , , , A87)) -> 1034 | S87: =R87 & TEXT(B87, "yyyymmdd") -> 103420251218
A88: 1034 | B88: 2025-12-31 | C88: 52.205882 | D88: 50.735294 | E88: 0 | F88: 0 | G88: 71 | H88: 69 | I88: 136 | J88: 136 | K88: 0 | L88: 0 | M88: 0.20602817 | N88: 0.1906087 | O88: =_xlfn.XLOOKUP(S88, AnglePowerMatching!$H:$H, AnglePowerMatching!$C:$C, "NaN") -> 66 | P88: =_xlfn.XLOOKUP(S88, AnglePowerMatching!$H:$H, AnglePowerMatching!$D:$D, "NaN") -> 5 masker | Q88: =NOT(OR(C88=0,D88=0)) -> TRUE | R88: =VALUE(_xlfn.TEXTBEFORE(A88, {"L","R"}, , , , A88)) -> 1034 | S88: =R88 & TEXT(B88, "yyyymmdd") -> 103420251231
A89: 1034 | B89: 2026-01-13 | C89: 61.666667 | D89: 61.016949 | E89: 0 | F89: 2 | G89: 74 | H89: 72 | I89: 120 | J89: 120 | K89: 0 | L89: 1.6666667 | M89: 0.28716216 | N89: 0.28869444 | O89: =_xlfn.XLOOKUP(S89, AnglePowerMatching!$H:$H, AnglePowerMatching!$C:$C, "NaN") -> 66 | P89: =_xlfn.XLOOKUP(S89, AnglePowerMatching!$H:$H, AnglePowerMatching!$D:$D, "NaN") -> 3 masker | Q89: =NOT(OR(C89=0,D89=0)) -> TRUE | R89: =VALUE(_xlfn.TEXTBEFORE(A89, {"L","R"}, , , , A89)) -> 1034 | S89: =R89 & TEXT(B89, "yyyymmdd") -> 103420260113
A90: 1034 | B90: 2026-01-14 | C90: 49.586777 | D90: 59.166667 | E90: 0 | F90: 0 | G90: 60 | H90: 71 | I90: 121 | J90: 120 | K90: 0 | L90: 0 | M90: 0.19216667 | N90: 0.21511268 | O90: =_xlfn.XLOOKUP(S90, AnglePowerMatching!$H:$H, AnglePowerMatching!$C:$C, "NaN") -> 66 | P90: =_xlfn.XLOOKUP(S90, AnglePowerMatching!$H:$H, AnglePowerMatching!$D:$D, "NaN") -> 5 masker | Q90: =NOT(OR(C90=0,D90=0)) -> TRUE | R90: =VALUE(_xlfn.TEXTBEFORE(A90, {"L","R"}, , , , A90)) -> 1034 | S90: =R90 & TEXT(B90, "yyyymmdd") -> 103420260114
A91: 9450L | B91: 2025-08-18 | C91: 76.470588 | D91: 65.833333 | E91: 1 | F91: 0 | G91: 91 | H91: 79 | I91: 120 | J91: 120 | K91: 0.83333333 | L91: 0 | M91: 0.2632967 | N91: 0.24758228 | O91: =_xlfn.XLOOKUP(S91, AnglePowerMatching!$H:$H, AnglePowerMatching!$C:$C, "NaN") -> NaN | P91: =_xlfn.XLOOKUP(S91, AnglePowerMatching!$H:$H, AnglePowerMatching!$D:$D, "NaN") -> NaN | Q91: =NOT(OR(C91=0,D91=0)) -> TRUE | R91: =VALUE(_xlfn.TEXTBEFORE(A91, {"L","R"}, , , , A91)) -> 9450 | S91: =R91 & TEXT(B91, "yyyymmdd") -> 945020250818
A92: 948L | B92: 2025-07-24 | D92: 0 | E92: 0 | F92: 5 | G92: 0 | H92: 0 | I92: 0 | J92: 6 | K92: 0 | L92: 83.333333 | O92: =_xlfn.XLOOKUP(S92, AnglePowerMatching!$H:$H, AnglePowerMatching!$C:$C, "NaN") -> NaN | P92: =_xlfn.XLOOKUP(S92, AnglePowerMatching!$H:$H, AnglePowerMatching!$D:$D, "NaN") -> NaN | Q92: =NOT(OR(C92=0,D92=0)) -> FALSE | R92: =VALUE(_xlfn.TEXTBEFORE(A92, {"L","R"}, , , , A92)) -> 948 | S92: =R92 & TEXT(B92, "yyyymmdd") -> 94820250724
A93: 948L | B93: 2025-07-24 | D93: 0 | E93: 0 | F93: 5 | G93: 0 | H93: 0 | I93: 0 | J93: 6 | K93: 0 | L93: 83.333333 | O93: =_xlfn.XLOOKUP(S93, AnglePowerMatching!$H:$H, AnglePowerMatching!$C:$C, "NaN") -> NaN | P93: =_xlfn.XLOOKUP(S93, AnglePowerMatching!$H:$H, AnglePowerMatching!$D:$D, "NaN") -> NaN | Q93: =NOT(OR(C93=0,D93=0)) -> FALSE | R93: =VALUE(_xlfn.TEXTBEFORE(A93, {"L","R"}, , , , A93)) -> 948 | S93: =R93 & TEXT(B93, "yyyymmdd") -> 94820250724
A94: 948L | B94: 2025-07-24 | D94: 42.857143 | E94: 0 | F94: 1 | G94: 0 | H94: 6 | I94: 0 | J94: 15 | K94: 0 | L94: 6.6666667 | N94: 0.53583333 | O94: =_xlfn.XLOOKUP(S94, AnglePowerMatching!$H:$H, AnglePowerMatching!$C:$C, "NaN") -> NaN | P94: =_xlfn.XLOOKUP(S94, AnglePowerMatching!$H:$H, AnglePowerMatching!$D:$D, "NaN") -> NaN | Q94: =NOT(OR(C94=0,D94=0)) -> FALSE | R94: =VALUE(_xlfn.TEXTBEFORE(A94, {"L","R"}, , , , A94)) -> 948 | S94: =R94 & TEXT(B94, "yyyymmdd") -> 94820250724
A95: 948L | B95: 2025-07-25 | C95: 0 | D95: 100 | E95: 0 | F95: 0 | G95: 0 | H95: 2 | I95: 1 | J95: 2 | K95: 0 | L95: 0 | N95: 0.496 | O95: =_xlfn.XLOOKUP(S95, AnglePowerMatching!$H:$H, AnglePowerMatching!$C:$C, "NaN") -> 66 | P95: =_xlfn.XLOOKUP(S95, AnglePowerMatching!$H:$H, AnglePowerMatching!$D:$D, "NaN") -> 3 | Q95: =NOT(OR(C95=0,D95=0)) -> FALSE | R95: =VALUE(_xlfn.TEXTBEFORE(A95, {"L","R"}, , , , A95)) -> 948 | S95: =R95 & TEXT(B95, "yyyymmdd") -> 94820250725
A96: 948L | B96: 2025-07-25 | C96: 88.372093 | D96: 90.217391 | E96: 8 | F96: 2 | G96: 76 | H96: 83 | I96: 94 | J96: 94 | K96: 8.5106383 | L96: 2.1276596 | M96: 0.43493421 | N96: 0.40443373 | O96: =_xlfn.XLOOKUP(S96, AnglePowerMatching!$H:$H, AnglePowerMatching!$C:$C, "NaN") -> 66 | P96: =_xlfn.XLOOKUP(S96, AnglePowerMatching!$H:$H, AnglePowerMatching!$D:$D, "NaN") -> 3 | Q96: =NOT(OR(C96=0,D96=0)) -> TRUE | R96: =VALUE(_xlfn.TEXTBEFORE(A96, {"L","R"}, , , , A96)) -> 948 | S96: =R96 & TEXT(B96, "yyyymmdd") -> 94820250725
A97: 948L | B97: 2025-07-26 | C97: 91.304348 | D97: 86.486486 | E97: 9 | F97: 14 | G97: 105 | H97: 96 | I97: 124 | J97: 125 | K97: 7.2580645 | L97: 11.2 | M97: 0.37724762 | N97: 0.46075 | O97: =_xlfn.XLOOKUP(S97, AnglePowerMatching!$H:$H, AnglePowerMatching!$C:$C, "NaN") -> NaN | P97: =_xlfn.XLOOKUP(S97, AnglePowerMatching!$H:$H, AnglePowerMatching!$D:$D, "NaN") -> NaN | Q97: =NOT(OR(C97=0,D97=0)) -> TRUE | R97: =VALUE(_xlfn.TEXTBEFORE(A97, {"L","R"}, , , , A97)) -> 948 | S97: =R97 & TEXT(B97, "yyyymmdd") -> 94820250726
A98: 948L | B98: 2025-07-27 | C98: 50 | D98: 50 | E98: 0 | F98: 0 | G98: 2 | H98: 2 | I98: 4 | J98: 4 | K98: 0 | L98: 0 | M98: 0.188 | N98: 0.387 | O98: =_xlfn.XLOOKUP(S98, AnglePowerMatching!$H:$H, AnglePowerMatching!$C:$C, "NaN") -> 66 | P98: =_xlfn.XLOOKUP(S98, AnglePowerMatching!$H:$H, AnglePowerMatching!$D:$D, "NaN") -> 5 | Q98: =NOT(OR(C98=0,D98=0)) -> TRUE | R98: =VALUE(_xlfn.TEXTBEFORE(A98, {"L","R"}, , , , A98)) -> 948 | S98: =R98 & TEXT(B98, "yyyymmdd") -> 94820250727
A99: 948L | B99: 2025-07-27 | C99: 87.826087 | D99: 89.565217 | E99: 0 | F99: 0 | G99: 101 | H99: 103 | I99: 115 | J99: 115 | K99: 0 | L99: 0 | M99: 0.28676238 | N99: 0.28343689 | O99: =_xlfn.XLOOKUP(S99, AnglePowerMatching!$H:$H, AnglePowerMatching!$C:$C, "NaN") -> 66 | P99: =_xlfn.XLOOKUP(S99, AnglePowerMatching!$H:$H, AnglePowerMatching!$D:$D, "NaN") -> 5 | Q99: =NOT(OR(C99=0,D99=0)) -> TRUE | R99: =VALUE(_xlfn.TEXTBEFORE(A99, {"L","R"}, , , , A99)) -> 948 | S99: =R99 & TEXT(B99, "yyyymmdd") -> 94820250727
A100: 948L | B100: 2025-07-28 | C100: 100 | D100: 50 | E100: 0 | F100: 0 | G100: 1 | H100: 1 | I100: 1 | J100: 2 | K100: 0 | L100: 0 | M100: 0.476 | N100: 0.383 | O100: =_xlfn.XLOOKUP(S100, AnglePowerMatching!$H:$H, AnglePowerMatching!$C:$C, "NaN") -> 66 | P100: =_xlfn.XLOOKUP(S100, AnglePowerMatching!$H:$H, AnglePowerMatching!$D:$D, "NaN") -> 10 | Q100: =NOT(OR(C100=0,D100=0)) -> TRUE | R100: =VALUE(_xlfn.TEXTBEFORE(A100, {"L","R"}, , , , A100)) -> 948 | S100: =R100 & TEXT(B100, "yyyymmdd") -> 94820250728
A101: 948L | B101: 2025-07-28 | C101: 100 | D101: 100 | E101: 0 | F101: 0 | G101: 1 | H101: 2 | I101: 1 | J101: 2 | K101: 0 | L101: 0 | M101: 0.575 | N101: 0.683 | O101: =_xlfn.XLOOKUP(S101, AnglePowerMatching!$H:$H, AnglePowerMatching!$C:$C, "NaN") -> 66 | P101: =_xlfn.XLOOKUP(S101, AnglePowerMatching!$H:$H, AnglePowerMatching!$D:$D, "NaN") -> 10 | Q101: =NOT(OR(C101=0,D101=0)) -> TRUE | R101: =VALUE(_xlfn.TEXTBEFORE(A101, {"L","R"}, , , , A101)) -> 948 | S101: =R101 & TEXT(B101, "yyyymmdd") -> 94820250728
A102: 948L | B102: 2025-07-28 | C102: 100 | D102: 66.666667 | E102: 1 | F102: 0 | G102: 5 | H102: 4 | I102: 6 | J102: 6 | K102: 16.666667 | L102: 0 | M102: 0.4664 | N102: 0.48775 | O102: =_xlfn.XLOOKUP(S102, AnglePowerMatching!$H:$H, AnglePowerMatching!$C:$C, "NaN") -> 66 | P102: =_xlfn.XLOOKUP(S102, AnglePowerMatching!$H:$H, AnglePowerMatching!$D:$D, "NaN") -> 10 | Q102: =NOT(OR(C102=0,D102=0)) -> TRUE | R102: =VALUE(_xlfn.TEXTBEFORE(A102, {"L","R"}, , , , A102)) -> 948 | S102: =R102 & TEXT(B102, "yyyymmdd") -> 94820250728
A103: 948L | B103: 2025-07-28 | C103: 93.814433 | D103: 88.77551 | E103: 23 | F103: 22 | G103: 91 | H103: 87 | I103: 120 | J103: 120 | K103: 19.166667 | L103: 18.333333 | M103: 0.54502198 | N103: 0.55297701 | O103: =_xlfn.XLOOKUP(S103, AnglePowerMatching!$H:$H, AnglePowerMatching!$C:$C, "NaN") -> 66 | P103: =_xlfn.XLOOKUP(S103, AnglePowerMatching!$H:$H, AnglePowerMatching!$D:$D, "NaN") -> 10 | Q103: =NOT(OR(C103=0,D103=0)) -> TRUE | R103: =VALUE(_xlfn.TEXTBEFORE(A103, {"L","R"}, , , , A103)) -> 948 | S103: =R103 & TEXT(B103, "yyyymmdd") -> 94820250728
A104: 948L | B104: 2025-07-29 | C104: 84.931507 | D104: 89.74359 | E104: 47 | F104: 42 | G104: 62 | H104: 70 | I104: 120 | J104: 120 | K104: 39.166667 | L104: 35 | M104: 0.61246774 | N104: 0.63437143 | O104: =_xlfn.XLOOKUP(S104, AnglePowerMatching!$H:$H, AnglePowerMatching!$C:$C, "NaN") -> 66 | P104: =_xlfn.XLOOKUP(S104, AnglePowerMatching!$H:$H, AnglePowerMatching!$D:$D, "NaN") -> 3 | Q104: =NOT(OR(C104=0,D104=0)) -> TRUE | R104: =VALUE(_xlfn.TEXTBEFORE(A104, {"L","R"}, , , , A104)) -> 948 | S104: =R104 & TEXT(B104, "yyyymmdd") -> 94820250729
A105: 948L | B105: 2025-07-30 | D105: 0 | E105: 0 | F105: 1 | G105: 0 | H105: 0 | I105: 0 | J105: 2 | K105: 0 | L105: 50 | O105: =_xlfn.XLOOKUP(S105, AnglePowerMatching!$H:$H, AnglePowerMatching!$C:$C, "NaN") -> 90 | P105: =_xlfn.XLOOKUP(S105, AnglePowerMatching!$H:$H, AnglePowerMatching!$D:$D, "NaN") -> 3 | Q105: =NOT(OR(C105=0,D105=0)) -> FALSE | R105: =VALUE(_xlfn.TEXTBEFORE(A105, {"L","R"}, , , , A105)) -> 948 | S105: =R105 & TEXT(B105, "yyyymmdd") -> 94820250730
A106: 948L | B106: 2025-07-30 | C106: 0 | E106: 1 | F106: 2 | G106: 0 | H106: 0 | I106: 2 | J106: 2 | K106: 50 | L106: 100 | O106: =_xlfn.XLOOKUP(S106, AnglePowerMatching!$H:$H, AnglePowerMatching!$C:$C, "NaN") -> 90 | P106: =_xlfn.XLOOKUP(S106, AnglePowerMatching!$H:$H, AnglePowerMatching!$D:$D, "NaN") -> 3 | Q106: =NOT(OR(C106=0,D106=0)) -> FALSE | R106: =VALUE(_xlfn.TEXTBEFORE(A106, {"L","R"}, , , , A106)) -> 948 | S106: =R106 & TEXT(B106, "yyyymmdd") -> 94820250730
A107: 948L | B107: 2025-07-30 | C107: 91.780822 | D107: 89.534884 | E107: 42 | F107: 30 | G107: 67 | H107: 77 | I107: 115 | J107: 116 | K107: 36.521739 | L107: 25.862069 | M107: 0.51428358 | N107: 0.53480519 | O107: =_xlfn.XLOOKUP(S107, AnglePowerMatching!$H:$H, AnglePowerMatching!$C:$C, "NaN") -> 90 | P107: =_xlfn.XLOOKUP(S107, AnglePowerMatching!$H:$H, AnglePowerMatching!$D:$D, "NaN") -> 3 | Q107: =NOT(OR(C107=0,D107=0)) -> TRUE | R107: =VALUE(_xlfn.TEXTBEFORE(A107, {"L","R"}, , , , A107)) -> 948 | S107: =R107 & TEXT(B107, "yyyymmdd") -> 94820250730
A108: 948L | B108: 2025-07-31 | C108: 83.478261 | D108: 87.610619 | E108: 5 | F108: 7 | G108: 96 | H108: 99 | I108: 120 | J108: 120 | K108: 4.1666667 | L108: 5.8333333 | M108: 0.41176042 | N108: 0.43931313 | O108: =_xlfn.XLOOKUP(S108, AnglePowerMatching!$H:$H, AnglePowerMatching!$C:$C, "NaN") -> 90 | P108: =_xlfn.XLOOKUP(S108, AnglePowerMatching!$H:$H, AnglePowerMatching!$D:$D, "NaN") -> 5 | Q108: =NOT(OR(C108=0,D108=0)) -> TRUE | R108: =VALUE(_xlfn.TEXTBEFORE(A108, {"L","R"}, , , , A108)) -> 948 | S108: =R108 & TEXT(B108, "yyyymmdd") -> 94820250731
A109: 948L | B109: 2025-08-01 | C109: 96.039604 | D109: 91.818182 | E109: 29 | F109: 21 | G109: 97 | H109: 101 | I109: 130 | J109: 131 | K109: 22.307692 | L109: 16.030534 | M109: 0.51113402 | N109: 0.49015842 | O109: =_xlfn.XLOOKUP(S109, AnglePowerMatching!$H:$H, AnglePowerMatching!$C:$C, "NaN") -> 90 | P109: =_xlfn.XLOOKUP(S109, AnglePowerMatching!$H:$H, AnglePowerMatching!$D:$D, "NaN") -> 10 | Q109: =NOT(OR(C109=0,D109=0)) -> TRUE | R109: =VALUE(_xlfn.TEXTBEFORE(A109, {"L","R"}, , , , A109)) -> 948 | S109: =R109 & TEXT(B109, "yyyymmdd") -> 94820250801
A110: 948L | B110: 2025-08-02 | C110: 92.537313 | D110: 96.240602 | E110: 0 | F110: 2 | G110: 124 | H110: 128 | I110: 134 | J110: 135 | K110: 0 | L110: 1.4814815 | M110: 0.38116129 | N110: 0.37492969 | O110: =_xlfn.XLOOKUP(S110, AnglePowerMatching!$H:$H, AnglePowerMatching!$C:$C, "NaN") -> NaN | P110: =_xlfn.XLOOKUP(S110, AnglePowerMatching!$H:$H, AnglePowerMatching!$D:$D, "NaN") -> NaN | Q110: =NOT(OR(C110=0,D110=0)) -> TRUE | R110: =VALUE(_xlfn.TEXTBEFORE(A110, {"L","R"}, , , , A110)) -> 948 | S110: =R110 & TEXT(B110, "yyyymmdd") -> 94820250802
...
